Workbook

Sheet LaggarTT
A1: Brand | B1: Артикул | C1: Description | D1: модель | E1: тип | F1: высота | G1: длина | H1: глубина | I1: сторона | J1: flow | K1: Вес нетто | L1: Вес брутто | M1: Heat Output | N1: GTIN code | P1: Расчет ТТ | Q1: Проверка
A2: - | B2: 63008524 | C2: стальная клипса BT16 | D2: - | E2: - | F2: - | G2: - | H2: - | I2: - | J2: - | K2: - | L2: -
A3: - | B3: 8755C50003 | C3: Кран Маевского | D3: - | E3: - | F3: - | G3: - | H3: - | I3: - | J3: - | K3: - | L3: -
A4: - | B4: 8755C50008 | C4: Уголок, G 1/2 10/11 | D4: - | E4: - | F4: - | G4: - | H4: - | I4: - | J4: - | K4: - | L4: -
A5: - | B5: 8755C80002 | C5: Фиксатор ПА средний | D5: - | E5: - | F5: - | G5: - | H5: - | I5: - | J5: - | K5: - | L5: -
A6: - | B6: 8755C80003 | C6: Штырек ПА средний | D6: - | E6: - | F6: - | G6: - | H6: - | I6: - | J6: - | K6: - | L6: -
A7: - | B7: 8755C80004 | C7: защитный уголок малый | D7: - | E7: - | F7: - | G7: - | H7: - | I7: - | J7: - | K7: - | L7: -
A8: - | B8: 8755C80005 | C8: защитный уголок средний | D8: - | E8: - | F8: - | G8: - | H8: - | I8: - | J8: - | K8: - | L8: -
A9: - | B9: 8755C80006 | C9: защитный уголок большой | D9: - | E9: - | F9: - | G9: - | H9: - | I9: - | J9: - | K9: - | L9: -
A10: - | B10: 8755C80007 | C10: Фиксатор ПА боковой | D10: - | E10: - | F10: - | G10: - | H10: - | I10: - | J10: - | K10: - | L10: -
A11: - | B11: 8755C80008 | C11: Штырек ПА боковой | D11: - | E11: - | F11: - | G11: - | H11: - | I11: - | J11: - | K11: - | L11: -
A12: - | B12: 8755D31130 | C12: Боковая панель 10,11 300 l | D12: - | E12: 10 | F12: 300 | G12: - | H12: - | I12: - | J12: - | K12: - | L12: -
A13: - | B13: 8755D31030 | C13: Боковая панель 10,11 300 r | D13: - | E13: 10 | F13: 300 | G13: - | H13: - | I13: - | J13: - | K13: - | L13: -
A14: - | B14: 8755D31140 | C14: Боковая панель 10,11 400 l | D14: - | E14: 10 | F14: 400 | G14: - | H14: - | I14: - | J14: - | K14: - | L14: -
A15: - | B15: 8755D31040 | C15: Боковая панель 10,11 400 r | D15: - | E15: 10 | F15: 400 | G15: - | H15: - | I15: - | J15: - | K15: - | L15: -
A16: - | B16: 8755D31150 | C16: Боковая панель 10,11 500 l | D16: - | E16: 10 | F16: 500 | G16: - | H16: - | I16: - | J16: - | K16: - | L16: -
A17: - | B17: 8755D31050 | C17: Боковая панель 10,11 500 r | D17: - | E17: 10 | F17: 500 | G17: - | H17: - | I17: - | J17: - | K17: - | L17: -
A18: - | B18: 8755D31160 | C18: Боковая панель 10,11 600 l | D18: - | E18: 10 | F18: 600 | G18: - | H18: - | I18: - | J18: - | K18: - | L18: -
A19: - | B19: 8755D31060 | C19: Боковая панель 10,11 600 r | D19: - | E19: 10 | F19: 600 | G19: - | H19: - | I19: - | J19: - | K19: - | L19: -
A20: - | B20: 8755D31190 | C20: Боковая панель 10,11 900 l | D20: - | E20: 10 | F20: 900 | G20: - | H20: - | I20: - | J20: - | K20: - | L20: -
A21: - | B21: 8755D31090 | C21: Боковая панель 10,11 900 r | D21: - | E21: 10 | F21: 900 | G21: - | H21: - | I21: - | J21: - | K21: - | L21: -
A22: - | B22: 8755D32030 | C22: Боковая панель 20,22 300 l,r | D22: - | E22: 20 | F22: 300 | G22: - | H22: - | I22: - | J22: - | K22: - | L22: -
A23: - | B23: 8755D32040 | C23: Боковая панель 20,22 400 l,r | D23: - | E23: 20 | F23: 400 | G23: - | H23: - | I23: - | J23: - | K23: - | L23: -
... A26: - | B26: 8755D32090 | C26: Боковая панель 20,22 900 l,r | D26: - | E26: 20 | F26: 900 | G26: - | H26: - | I26: - | J26: - | K26: - | L26: -
A27: - | B27: 8755D70065 | C27: Латунная заглушка | D27: - | E27: - | F27: - | G27: - | H27: - | I27: - | J27: - | K27: - | L27: -
A28: - | B28: 8755D70067 | C28: Клипса Buderus короткая | D28: - | E28: - | F28: - | G28: - | H28: - | I28: - | J28: - | K28: - | L28: -
A29: - | B29: 8755D70068 | C29: Клипса Buderus длинная | D29: - | E29: - | F29: - | G29: - | H29: - | I29: - | J29: - | K29: - | L29: -
A30: - | B30: 8755D70071 | C30: Фиксаторы (набор)-8755D70071 | D30: - | E30: - | F30: - | G30: - | H30: - | I30: - | J30: - | K30: - | L30: -
A31: - | B31: 8755D70072 | C31: Клипса (набор) | D31: - | E31: - | F31: - | G31: - | H31: - | I31: - | J31: - | K31: - | L31: -
A32: - | B32: 8755D70073 | C32: Фиксаторы (набор) | D32: - | E32: - | F32: - | G32: - | H32: - | I32: - | J32: - | K32: - | L32: -
A33: - | B33: 8755D70074 | C33: Фиксаторы (набор)-8755D70074 | D33: - | E33: - | F33: - | G33: - | H33: - | I33: - | J33: - | K33: - | L33: -
A34: - | B34: 8755D12104 | C34: Гриль 21,400 | D34: - | E34: - | F34: - | G34: 400 | H34: - | I34: - | J34: - | K34: - | L34: -
A35: - | B35: 8755D12105 | C35: Гриль 21,500 | D35: - | E35: - | F35: - | G35: 500 | H35: - | I35: - | J35: - | K35: - | L35: -
A36: - | B36: 8755D12106 | C36: Гриль 21,600 | D36: - | E36: - | F36: - | G36: 600 | H36: - | I36: - | J36: - | K36: - | L36: -
A37: - | B37: 8755D12107 | C37: Гриль 21,700 | D37: - | E37: - | F37: - | G37: 700 | H37: - | I37: - | J37: - | K37: - | L37: -
A38: - | B38: 8755D12108 | C38: Гриль 21,800 | D38: - | E38: - | F38: - | G38: 800 | H38: - | I38: - | J38: - | K38: - | L38: -
A39: - | B39: 8755D12109 | C39: Гриль 21,900 | D39: - | E39: - | F39: - | G39: 900 | H39: - | I39: - | J39: - | K39: - | L39: -
A40: - | B40: 8755D12110 | C40: Гриль 21,1000 | D40: - | E40: - | F40: - | G40: 1000 | H40: - | I40: - | J40: - | K40: - | L40: -
A41: - | B41: 8755D12111 | C41: Гриль 21,1100 | D41: - | E41: - | F41: - | G41: 1100 | H41: - | I41: - | J41: - | K41: - | L41: -
A42: - | B42: 8755D12112 | C42: Гриль 21,1200 | D42: - | E42: - | F42: - | G42: 1200 | H42: - | I42: - | J42: - | K42: - | L42: -
...

Sheet METEOR
G1: LaggarTT
A2: 1 | B2: 7724601304 | C2: Радиатор METEOR Classic K-Profil 10/300/400 | E2: 225.04 | G2: 7724701304 | H2: =VLOOKUP(G2,LaggarTT!B128:M2557,12,0) -> 225.04 | I2: =IF(E2=H2,"Ok","NO") -> Ok
A3: 2 | B3: 7724601305 | C3: Радиатор METEOR Classic K-Profil 10/300/500 | E3: 281.3 | G3: 7724701305 | H3: =VLOOKUP(G3,LaggarTT!B129:M2558,12,0) -> 281.3 | I3: =IF(E3=H3,"Ok","NO") -> Ok
A4: 3 | B4: 7724601306 | C4: Радиатор METEOR Classic K-Profil 10/300/600 | E4: 337.56 | G4: 7724701306 | H4: =VLOOKUP(G4,LaggarTT!B130:M2559,12,0) -> 337.56 | I4: =IF(E4=H4,"Ok","NO") -> Ok
A5: 4 | B5: 7724601307 | C5: Радиатор METEOR Classic K-Profil 10/300/700 | E5: 393.82 | G5: 7724701307 | H5: =VLOOKUP(G5,LaggarTT!B131:M2560,12,0) -> 393.82 | I5: =IF(E5=H5,"Ok","NO") -> Ok
A6: 5 | B6: 7724601308 | C6: Радиатор METEOR Classic K-Profil 10/300/800 | E6: 450.08 | G6: 7724701308 | H6: =VLOOKUP(G6,LaggarTT!B132:M2561,12,0) -> 450.08 | I6: =IF(E6=H6,"Ok","NO") -> Ok
A7: 6 | B7: 7724601309 | C7: Радиатор METEOR Classic K-Profil 10/300/900 | E7: 506.34 | G7: 7724701309 | H7: =VLOOKUP(G7,LaggarTT!B133:M2562,12,0) -> 506.34 | I7: =IF(E7=H7,"Ok","NO") -> Ok
A8: 7 | B8: 7724601310 | C8: Радиатор METEOR Classic K-Profil 10/300/1000 | E8: 562.6 | G8: 7724701310 | H8: =VLOOKUP(G8,LaggarTT!B134:M2563,12,0) -> 562.6 | I8: =IF(E8=H8,"Ok","NO") -> Ok
A9: 8 | B9: 7724601311 | C9: Радиатор METEOR Classic K-Profil 10/300/1100 | E9: 618.86 | G9: 7724701311 | H9: =VLOOKUP(G9,LaggarTT!B135:M2564,12,0) -> 618.86 | I9: =IF(E9=H9,"Ok","NO") -> Ok
A10: 9 | B10: 7724601312 | C10: Радиатор METEOR Classic K-Profil 10/300/1200 | E10: 675.12 | G10: 7724701312 | H10: =VLOOKUP(G10,LaggarTT!B136:M2565,12,0) -> 675.12 | I10: =IF(E10=H10,"Ok","NO") -> Ok
A11: 10 | B11: 7724601313 | C11: Радиатор METEOR Classic K-Profil 10/300/1300 | E11: 731.38 | G11: 7724701313 | H11: =VLOOKUP(G11,LaggarTT!B137:M2566,12,0) -> 731.38 | I11: =IF(E11=H11,"Ok","NO") -> Ok
A12: 11 | B12: 7724601314 | C12: Радиатор METEOR Classic K-Profil 10/300/1400 | E12: 787.64 | G12: 7724701314 | H12: =VLOOKUP(G12,LaggarTT!B138:M2567,12,0) -> 787.64 | I12: =IF(E12=H12,"Ok","NO") -> Ok
A13: 12 | B13: 7724601315 | C13: Радиатор METEOR Classic K-Profil 10/300/1500 | E13: 843.9 | G13: 7724701315 | H13: =VLOOKUP(G13,LaggarTT!B139:M2568,12,0) -> 843.9 | I13: =IF(E13=H13,"Ok","NO") -> Ok
... A18: 17 | B18: 7724601320 | C18: Радиатор METEOR Classic K-Profil 10/300/2000 | E18: 1125.2 | G18: 7724701320 | H18: =VLOOKUP(G18,LaggarTT!B144:M2573,12,0) -> 1125.2 | I18: =IF(E18=H18,"Ok","NO") -> Ok
A19: 18 | B19: #N/A | C19: #N/A | E19: #N/A | G19: #N/A | H19: =VLOOKUP(G19,LaggarTT!B145:M2574,12,0) -> #N/A | I19: =IF(E19=H19,"Ok","NO") -> #N/A
A20: 19 | B20: #N/A | C20: #N/A | E20: #N/A | G20: #N/A | H20: =VLOOKUP(G20,LaggarTT!B146:M2575,12,0) -> #N/A | I20: =IF(E20=H20,"Ok","NO") -> #N/A
A21: 20 | B21: #N/A | C21: #N/A | E21: #N/A | G21: #N/A | H21: =VLOOKUP(G21,LaggarTT!B147:M2576,12,0) -> #N/A | I21: =IF(E21=H21,"Ok","NO") -> #N/A
A22: 21 | B22: #N/A | C22: #N/A | E22: #N/A | G22: #N/A | H22: =VLOOKUP(G22,LaggarTT!B148:M2577,12,0) -> #N/A | I22: =IF(E22=H22,"Ok","NO") -> #N/A
A23: 22 | B23: #N/A | C23: #N/A | E23: #N/A | G23: #N/A | H23: =VLOOKUP(G23,LaggarTT!B149:M2578,12,0) -> #N/A | I23: =IF(E23=H23,"Ok","NO") -> #N/A
A24: 23 | B24: #N/A | C24: #N/A | E24: #N/A | G24: #N/A | H24: =VLOOKUP(G24,LaggarTT!B150:M2579,12,0) -> #N/A | I24: =IF(E24=H24,"Ok","NO") -> #N/A
A25: 24 | B25: #N/A | C25: #N/A | E25: #N/A | G25: #N/A | H25: =VLOOKUP(G25,LaggarTT!B151:M2580,12,0) -> #N/A | I25: =IF(E25=H25,"Ok","NO") -> #N/A
A26: 25 | B26: #N/A | C26: #N/A | E26: #N/A | G26: #N/A | H26: =VLOOKUP(G26,LaggarTT!B152:M2581,12,0) -> #N/A | I26: =IF(E26=H26,"Ok","NO") -> #N/A
A27: 26 | B27: #N/A | C27: #N/A | E27: #N/A | G27: #N/A | H27: =VLOOKUP(G27,LaggarTT!B153:M2582,12,0) -> #N/A | I27: =IF(E27=H27,"Ok","NO") -> #N/A
A28: 27 | B28: #N/A | C28: #N/A | E28: #N/A | G28: #N/A | H28: =VLOOKUP(G28,LaggarTT!B154:M2583,12,0) -> #N/A | I28: =IF(E28=H28,"Ok","NO") -> #N/A
A29: 28 | B29: 7724601404 | C29: Радиатор METEOR Classic K-Profil 10/400/400 | E29: 288.0512 | G29: 7724701404 | H29: =VLOOKUP(G29,LaggarTT!B155:M2584,12,0) -> 288.0512 | I29: =IF(E29=H29,"Ok","NO") -> Ok
A30: 29 | B30: 7724601405 | C30: Радиатор METEOR Classic K-Profil 10/400/500 | E30: 360.064 | G30: 7724701405 | H30: =VLOOKUP(G30,LaggarTT!B156:M2585,12,0) -> 360.064 | I30: =IF(E30=H30,"Ok","NO") -> Ok
A31: 30 | B31: 7724601406 | C31: Радиатор METEOR Classic K-Profil 10/400/600 | E31: 432.0768 | G31: 7724701406 | H31: =VLOOKUP(G31,LaggarTT!B157:M2586,12,0) -> 432.0768 | I31: =IF(E31=H31,"Ok","NO") -> Ok
A32: 31 | B32: 7724601407 | C32: Радиатор METEOR Classic K-Profil 10/400/700 | E32: 504.0896 | G32: 7724701407 | H32: =VLOOKUP(G32,LaggarTT!B158:M2587,12,0) -> 504.0896 | I32: =IF(E32=H32,"Ok","NO") -> Ok
A33: 32 | B33: 7724601408 | C33: Радиатор METEOR Classic K-Profil 10/400/800 | E33: 576.1024 | G33: 7724701408 | H33: =VLOOKUP(G33,LaggarTT!B159:M2588,12,0) -> 576.1024 | I33: =IF(E33=H33,"Ok","NO") -> Ok
A34: 33 | B34: 7724601409 | C34: Радиатор METEOR Classic K-Profil 10/400/900 | E34: 648.1152 | G34: 7724701409 | H34: =VLOOKUP(G34,LaggarTT!B160:M2589,12,0) -> 648.1152 | I34: =IF(E34=H34,"Ok","NO") -> Ok
A35: 34 | B35: 7724601410 | C35: Радиатор METEOR Classic K-Profil 10/400/1000 | E35: 720.128 | G35: 7724701410 | H35: =VLOOKUP(G35,LaggarTT!B161:M2590,12,0) -> 720.128 | I35: =IF(E35=H35,"Ok","NO") -> Ok
A36: 35 | B36: 7724601411 | C36: Радиатор METEOR Classic K-Profil 10/400/1100 | E36: 792.1408 | G36: 7724701411 | H36: =VLOOKUP(G36,LaggarTT!B162:M2591,12,0) -> 792.1408 | I36: =IF(E36=H36,"Ok","NO") -> Ok
A37: 36 | B37: 7724601412 | C37: Радиатор METEOR Classic K-Profil 10/400/1200 | E37: 864.1536 | G37: 7724701412 | H37: =VLOOKUP(G37,LaggarTT!B163:M2592,12,0) -> 864.1536 | I37: =IF(E37=H37,"Ok","NO") -> Ok
A38: 37 | B38: 7724601413 | C38: Радиатор METEOR Classic K-Profil 10/400/1300 | E38: 936.1664 | G38: 7724701413 | H38: =VLOOKUP(G38,LaggarTT!B164:M2593,12,0) -> 936.1664 | I38: =IF(E38=H38,"Ok","NO") -> Ok
A39: 38 | B39: 7724601414 | C39: Радиатор METEOR Classic K-Profil 10/400/1400 | E39: 1008.1792 | G39: 7724701414 | H39: =VLOOKUP(G39,LaggarTT!B165:M2594,12,0) -> 1008.1792 | I39: =IF(E39=H39,"Ok","NO") -> Ok
A40: 39 | B40: 7724601415 | C40: Радиатор METEOR Classic K-Profil 10/400/1500 | E40: 1080.192 | G40: 7724701415 | H40: =VLOOKUP(G40,LaggarTT!B166:M2595,12,0) -> 1080.192 | I40: =IF(E40=H40,"Ok","NO") -> Ok
... A45: 44 | B45: 7724601420 | C45: Радиатор METEOR Classic K-Profil 10/400/2000 | E45: 1440.256 | G45: 7724701420 | H45: =VLOOKUP(G45,LaggarTT!B171:M2600,12,0) -> 1440.256 | I45: =IF(E45=H45,"Ok","NO") -> Ok
A46: 45 | B46: #N/A | C46: #N/A | E46: #N/A | G46: #N/A | H46: =VLOOKUP(G46,LaggarTT!B172:M2601,12,0) -> #N/A | I46: =IF(E46=H46,"Ok","NO") -> #N/A
A47: 46 | B47: #N/A | C47: #N/A | E47: #N/A | G47: #N/A | H47: =VLOOKUP(G47,LaggarTT!B173:M2602,12,0) -> #N/A | I47: =IF(E47=H47,"Ok","NO") -> #N/A
A48: 47 | B48: #N/A | C48: #N/A | E48: #N/A | G48: #N/A | H48: =VLOOKUP(G48,LaggarTT!B174:M2603,12,0) -> #N/A | I48: =IF(E48=H48,"Ok","NO") -> #N/A
...
